Workbook

Sheet 0. Як користуватись
A1: Що це за файл | B1: Пояснення
A2: Призначення | B2: Робоча модель запуску виробництва класичного енергетичного напою в Україні на 5 000 л/міс (≈15 151 банка 0,33 л).
A3: Жовті комірки | B3: Це ваші вхідні дані: ціни сировини, вартість тари, ціна розливу, відпускна ціна. Міняйте їх під свої пропозиції від постачальників.
A4: Зелені комірки | B4: Результат розрахунку за формулами — чіпати не треба.
A5: Лист «Рецептура» | B5: Склад напою на 1 000 л з дозами і вартістю кожного інгредієнта.
A6: Лист «Собівартість» | B6: Повна собівартість 1 літра та 1 банки 0,33 л: сировина + тара + розлив + етикетка + втрати.
A7: Лист «Постачальники» | B7: Перелік реальних компаній з контактами, цінами й мінімальними партіями.
A8: Лист «Обладнання» | B8: Комплект обладнання для міні-цеху і бюджет запуску в трьох варіантах.
A9: Лист «P&L 5000 л» | B9: Місячна економіка: виручка, змінні витрати, постійні, прибуток, точка беззбитковості.
A10: Лист «Чекліст» | B10: Покроковий план запуску з регуляторних питань.
A11: Курс валют | B11: Використано офіційний курс НБУ: 1 USD = 44,86 грн, 1 EUR = 50,93 грн (вересень 2026).
A12: Головне попередження | B12: Ціни на харчові інгредієнти в Україні не публікуються стабільно: більшість постачальників дають ціну лише за запитом. Усі цифри тут — робочі орієнтири станом на вересень 2026 р., їх треба підтвердити комерційною пропозицією.

Sheet 1. Рецептура
A1: РЕЦЕПТУРА КЛАСИЧНОГО ЕНЕРГЕТИКА НА 1 000 Л ГОТОВОГО НАПОЮ
A2: Дози активних речовин відповідають рівню провідних брендів категорії: кофеїн 320 мг/л, таурин 4 г/л, цукор 105 г/л. Жовті клітинки «Ціна, грн/кг» — ваші дані від постачальника.
A4: Компонент | B4: Фасування / форма | C4: Доза на 1000 л | D4: Од. | E4: Ціна, грн/од. (ввід) | F4: Вартість на 1000 л, грн | G4: Вартість на 1 л, грн | H4: Примітка
A5: СИРОВИНА ОСНОВИ
A6: Цукор білий кристалічний | B6: мішок 50 кг | C6: 105 | D6: кг | E6: 31 | F6: =C6*E6 -> 3255 | G6: =F6/1000 -> 3.255 | H6: Ринковий орієнтир ≈31 грн/кг. Можна замінити частину на ГФС (від 39 грн/кг)
A7: СИРОВИНА АКТИВНА (те, що робить напій енергетиком)
A8: Кофеїн безводний (харчовий) | B8: 1 кг (Хімсейл) / 25 кг | C8: 0.32 | D8: кг | E8: 1090 | F8: =C8*E8 -> 348.8 | G8: =F8/1000 -> 0.3488 | H8: Хімсейл, Київ — 1 090 грн/кг у наявності, є специфікація 99,8 %. Не є прекурсором
A9: Таурин | B9: 1 кг / 25 кг | C9: 4 | D9: кг | E9: 900 | F9: =C9*E9 -> 3600 | G9: =F9/1000 -> 3.6 | H9: УВАГА: світова ціна таурину за 2024–2025 зросла з $2 до $10/кг (spot). 395 грн/кг — це старі залишки. Фіксуйте ціну контрактом
A10: D-глюкуронолактон (опційно) | B10: імпорт, від 25 кг | C10: 0 | D10: кг | E10: 3000 | F10: =C10*E10 -> 0 | G10: =F10/1000 -> 0 | H10: В Україні лише реактивна кваліфікація — харчову треба везти з Китаю. У більшості українських брендів його немає. Доза 0 = виключено; поставте 2,4 кг, щоб побачити повний класичний склад (+7 грн/л)
A11: Інозитол | B11: 1 кг / 25 кг | C11: 0.2 | D11: кг | E11: 700 | F11: =C11*E11 -> 140 | G11: =F11/1000 -> 0.14 | H11: ТОВ «Юнатіс» (Буча), ціна за запитом. Маркетинговий рядок у складі
A12: ВІТАМІНИ ГРУПИ B
A13: Нікотинамід (вітамін B3) | B13: 1 кг (ТОВ «СРП») | C13: 0.08 | D13: кг | E13: 2000 | F13: =C13*E13 -> 160 | G13: =F13/1000 -> 0.16 | H13: ТОВ «СРП» — 2 000 грн/кг за 1 кг, 1 900 грн/кг від 10 кг. Це 8 мг на 100 мл
A14: Кальцію D-пантотенат (B5) | B14: 1 кг (FERM) | C14: 0.02 | D14: кг | E14: 1200 | F14: =C14*E14 -> 24 | G14: =F14/1000 -> 0.024 | H14: FERM має фасовку 1 кг; ціну уточнюйте на сайті
A15: Піридоксину гідрохлорид (B6) | B15: 1 кг / 25 кг | C15: 0.02 | D15: кг | E15: 1300 | F15: =C15*E15 -> 26 | G15: =F15/1000 -> 0.026 | H15: Макрохім або «Система Оптимум» — ціна за запитом. Вносити останнім, при t ≤ 30 °C
A16: Ціанокобаламін 1 % (B12) | B16: імпорт / власне розведення | C16: 0.002 | D16: кг | E16: 500 | F16: =C16*E16 -> 1 | G16: =F16/1000 -> 0.001 | H16: 1 % trituration в Україні публічно не продають: або мікродоза чистого, або розводити самому
A17: РЕГУЛЯТОРИ КИСЛОТНОСТІ
A18: Лимонна кислота E330 | B18: мішок 25 кг (ТОВ «СРП») | C18: 0.8 | D18: кг | E18: 115 | F18: =C18*E18 -> 92 | G18: =F18/1000 -> 0.092 | H18: 115 грн/кг за мішок, 88 грн/кг від 40 мішків. Дозувати до pH 3,2–3,6, а не «за рецептом»
A19: Натрію цитрат E331 | B19: 25 кг (ХімСвіт) | C19: 0.3 | D19: кг | E19: 99 | F19: =C19*E19 -> 29.7 | G19: =F19/1000 -> 0.0297 | H19: 99 грн/кг (2 475 грн за 25 кг). Буфер, стабілізує pH під час зберігання
A20: СМАК, КОЛІР, ЗАХИСТ
A21: Ароматизатор харчовий «енергетик» | B21: за запитом (Трумікс / Б2Ф) | C21: 1 | D21: кг | E21: 900 | F21: =C21*E21 -> 900 | G21: =F21/1000 -> 0.9 | H21: Усі українські виробники дають ціну лише за запитом. Бажано 2 компоненти: верхні ноти + тіло смаку
A22: Барвник карамель E150d | B22: навал / фасовка | C22: 0.5 | D22: кг | E22: 250 | F22: =C22*E22 -> 125 | G22: =F22/1000 -> 0.125 | H22: Купувати навалом. Роздрібні фасовки «на 100 л» за 98 грн — це в 5–10 разів дорожче за кілограм
A23: Натрію бензоат E211 | B23: 0,5 кг (Klebrig) | C23: 0.15 | D23: кг | E23: 299 | F23: =C23*E23 -> 44.85 | G23: =F23/1000 -> 0.04485 | H23: Klebrig, Рівне — 299 грн/кг. Граничний вміст у напої 150 мг/л. Вносити ДО кислоти
A24: Калію сорбат E202 | B24: 0,5 кг (Klebrig) | C24: 0.2 | D24: кг | E24: 350 | F24: =C24*E24 -> 70 | G24: =F24/1000 -> 0.07 | H24: Klebrig — 1 398 грн за 4 кг = 350 грн/кг. Працює в парі з бензоатом, до 300 мг/л
A25: Діоксид вуглецю CO2 (харчовий) | B25: балон 40 л / 22 кг | C25: 5 | D25: кг | E25: 34 | F25: =C25*E25 -> 170 | G25: =F25/1000 -> 0.17 | H25: ТОВ «Пожарка», Київ — 748,80 грн за балон 22 кг. На 5 000 л/міс потрібен ≈1 балон
A26: Вода підготовлена (RO) | B26: власна підготовка | C26: 1000 | D26: л | E26: 0.15 | F26: =C26*E26 -> 150 | G26: =F26/1000 -> 0.15 | H26: Собівартість підготовки: сіль, фільтри, електрика, амортизація RO
A27: РАЗОМ СИРОВИНА | F27: =SUM(F5:F26) -> 9136.35 | G27: =F27/1000 -> 9.13635
A29: Контрольні показники готового напою: масова частка сухих речовин 10,5 ± 0,3 %; pH 3,2–3,6; CO2 4,5–5,5 г/л; кофеїн 320 мг/л (у банці 0,33 л — 105 мг, у 0,5 л — 160 мг).
A30: Увага: вміст кофеїну — це показник, який потрапляє на етикетку й перевіряється. Кожну партію здавайте в акредитовану лабораторію, цільовий допуск ±5 %.
A32: Вартість сировини на 1 банку 0,33 л, грн | C32: =G27*0.33 -> 3.0149955
A33: Вартість сировини на 1 банку 0,5 л, грн | C33: =G27*0.5 -> 4.568175

Sheet 2. Собівартість
A1: СОБІВАРТІСТЬ 1 ЛІТРА ТА 1 БАНКИ 0,33 Л
A2: Жовті клітинки — ввід, зелений результат. Спочатку перевірте, чи реальні для вас тара й ціна розливу — саме вони, а не сировина, визначають, чи буде проєкт прибутковим.
A4: Стаття витрат | B4: Од. | C4: На 1000 л | D4: На 1 л, грн | E4: На банку 0,33 л, грн | F4: Коментар | G4: Ставка
A5: Сировина за рецептурою | B5: грн | C5: ='1. Рецептура'!G27*1000 -> 9136.35 | D5: =C5/1000 -> 9.13635 | E5: =C5/1000*0.33 -> 3.0149955 | F5: Підсумок листа «Рецептура»
A6: Втрати сировини й напою 3 % | B6: % | C6: =SUM(C5)*G6 -> 274.0905 | D6: =C6/1000 -> 0.2740905 | E6: =C6/1000*0.33 -> 0.090449865 | F6: Розлив, промивка контуру, брак першої партії | G6: 0.03
A7: Вода технологічна і мийка (CIP) | B7: грн | C7: 120 | D7: =C7/1000 -> 0.12 | E7: =C7/1000*0.33 -> 0.0396 | F7: Мийні засоби, санітарія, промивка обладнання
A8: Алюмінієва банка 0,33 л з кришкою | B8: грн | C8: 25755 | D8: =C8/1000 -> 25.755 | E8: =C8/1000*0.33 -> 8.49915 | F8: 15 151 шт на місяць — тут 3 030 шт × 8,50 грн. Друкована банка або біла + слив
A9: Етикетка / друк / слив-плівка | B9: грн | C9: 4545 | D9: =C9/1000 -> 4.545 | E9: =C9/1000*0.33 -> 1.49985 | F9: 3 030 шт × 1,50 грн. Якщо банка вже друкована — тут 0
A10: Шринк-плівка (мультипак 4–6 шт.) | B10: грн | C10: 2424 | D10: =C10/1000 -> 2.424 | E10: =C10/1000*0.33 -> 0.79992 | F10: 3 030 шт × 0,80 грн — групова упаковка
A11: Гофрокороб і палетування | B11: грн | C11: 1818 | D11: =C11/1000 -> 1.818 | E11: =C11/1000*0.33 -> 0.59994 | F11: 3 030 шт × 0,60 грн — вторинна упаковка
A12: Розлив і закатка (контрактне виробництво) | B12: грн | C12: 4000 | D12: =C12/1000 -> 4 | E12: =C12/1000*0.33 -> 1.32 | F12: Орієнтир 4,00 грн за літр напою на чужій лінії. Якщо робите самі — тут лише електрика й амортизація
A13: Електрика, вода, стиснене повітря | B13: грн | C13: 0 | D13: =C13/1000 -> 0 | E13: =C13/1000*0.33 -> 0 | F13: Енергоносії на власному виробництві (на контракті — 0)
A14: Оплата праці виробничого персоналу | B14: грн | C14: 0 | D14: =C14/1000 -> 0 | E14: =C14/1000*0.33 -> 0 | F14: 2–3 оператори на 5 000 л/міс (на контракті — 0)
A15: Лабораторні аналізи (мікробіологія, кофеїн) | B15: грн | C15: 3500 | D15: =C15/1000 -> 3.5 | E15: =C15/1000*0.33 -> 1.155 | F15: Кожна партія
A16: Логістика до дистриб'ютора | B16: грн | C16: 3000 | D16: =C16/1000 -> 3 | E16: =C16/1000*0.33 -> 0.99 | F16: Доставка по місту/області
A17: Брак і повернення 1,5 % | B17: % | C17: =SUM(C5:C16)*G17 -> 818.58661 | D17: =C17/1000 -> 0.81858661 | E17: =C17/1000*0.33 -> 0.27013358 | F17: Бій банки, відмови мережі | G17: 0.015
A18: ПОВНА СОБІВАРТІСТЬ | C18: =SUM(C5:C17) -> 55391.027 | D18: =C18/1000 -> 55.391027 | E18: =C18/1000*0.33 -> 18.279039
A20: Як читати: сировина за рецептурою — це 3–5 грн на літр, а тара й розлив разом — у 2–3 рази більше. Саме тому контрактний розлив і закупівля банки великим обсягом дають найбільший ефект на прибуток.
A21: Цей розрахунок зроблено для варіанта А (контрактний розлив): тому «Електрика» і «Оплата праці» стоять на нулі — ви платите за літр на чужій лінії. Для варіанта Б (власний цех) поставте: Електрика ≈ 2 500 грн, Праця ≈ 6 000 грн, а «Розлив і закатка» = 0; у постійні витрати додайте оренду ≈ 37 500 грн. За обсягу 5 000 л/міс собівартість у власному цеху буде вищою (≈24 грн/банка), але за 30 000 л/міс вона падає до ≈17 грн/банка.
A23: ТАРА: БАНКА 0,33 Л ПРОТИ ПЕТ 0,5 Л — ЧОМУ СТАРТУВАТИ З ПЕТ
A24: Позиція | B24: Банка 0,33 л | C24: ПЕТ 0,5 л | D24: Коментар
A25: Тара, грн/шт | B25: 8.5 | C25: 4.68 | D25: Банка — оцінка (ціни не публікуються, Velena/CANPACK — за запитом). ПЕТ 0,5 л з горлом 28 мм — 749 грн/160 шт
A26: Кришка, грн/шт | B26: 0 | C26: 0.6 | D26: У банки кришка (easy-open end) входить у ціну банки, у ПЕТ — окремо
A27: Етикетка, грн/шт | B27: 0.6 | C27: 0.17 | D27: Самоклеюча етикетка від 0,17 грн (Арт Віжн). Для банки потрібен слив або друк
A28: Разом тара, грн/шт | B28: =B25+B26+B27 -> 9.1 | C28: =C25+C26+C27 -> 5.45 | D28: Формули
A29: Об'єм, л | B29: 0.33 | C29: 0.5
A30: Тара на 1 літр напою, грн | B30: =B28/B29 -> 27.575758 | C30: =C28/C29 -> 10.9 | D30: Ключовий показник — ПЕТ дешевший у 2,5 раза на літр
A31: Тара на 1 000 л, грн | B31: =B30*1000 -> 27575.758 | C31: =C30*1000 -> 10900 | D31: Різниця на місяць (5 000 л) — понад 80 000 грн
A33: Висновок: на 0,33 л у банці тара коштує ≈9,10 грн, на 0,5 л у ПЕТ — ≈5,45 грн. У перерахунку на літр це 27,6 грн проти 10,9 грн. Плюс банка вимагає мінімальної партії 20 000+ шт і брендованої тари від 100 000 шт — недосяжно на 5 000 л/міс. Тому: старт на ПЕТ 0,5 л, банка — після 20 000 л/міс.

Sheet 3. Постачальники
A1: ПОСТАЧАЛЬНИКИ СИРОВИНИ ТА ТАРИ В УКРАЇНІ
A2: Перевірені компанії з контактами. Ціни, позначені «за запитом», не публікуються — їх треба запросити комерційною пропозицією. Станом на вересень 2026 р.
A4: Категорія | B4: Компанія | C4: Місто | D4: Контакти | E4: Сайт | F4: Ціна / орієнтир | G4: Мін. партія | H4: Примітка
A5: СИРОВИНА — активні компоненти
A6: Кофеїн безводний | B6: ТОВ «Хімсейл» | C6: Київ, бул. Вацлава Гавела, 10 | D6: +38 (099) 537 90 00, +38 (097) 537 90 00, ximsale@gmail.com | E6: chemsale.com.ua | F6: 1 090 грн/кг, у наявності | G6: 1 кг | H6: Найкращий варіант для старту: є специфікація на 16 показників (вміст 99,8 %), продають і ФОП, і фізособам
A7: Кофеїн безводний (найгнучкіша фасовка) | B7: ТОВ «БІОЛАЙН» | C7: Лубни, Полтавська обл. | D7: biolin.com.ua, форма на сайті | E7: biolin.ub.ua | F7: 1 350 грн/кг; 1 200 грн/кг від 25 кг | G7: від 100 г | H7: Єдина компанія, що продає кофеїн від 100 грамів — ідеально для пробних варок
A8: Кофеїн безводний (найдешевший) | B8: PROFIPROT (через Bigl.ua / Prom.ua) | C8: онлайн | D8: через маркетплейс | E8: bigl.ua | F8: 990 грн/кг | G8: 1 кг | H8: Спортпит-бренд, а не B2B-дистриб'ютор: сертифікат і специфікацію під харчове виробництво можуть не надати
A9: Кофеїн безводний (для виробництва) | B9: ТОВ «Макрохім» | C9: Київ | D9: +380 (44) 495 27 00, info@macrochem.ua | E9: macrochem.ua | F9: за запитом | G9: від 1 кг | H9: Один із небагатьох, у кого в каталозі одночасно кофеїн, таурин, ніацинамід і B6 — можна закрити весь «актив» одним замовленням
A10: Кофеїн: легальність | B10: Довідково (не постачальник) | C10: — | D10: — | E10: zakon.rada.gov.ua/laws/show/770-2000-п | F10: ліцензія не потрібна | G10: — | H10: Кофеїн НЕ є прекурсором за Постановою КМУ № 770. Зареєстрований як фармсубстанція UA/12724/01/01 (виробник Jilin Shulan, Китай; імпортер — ФК «Здоров'я», Харків)
A11: Таурин | B11: PROFIPROT (через Bigl.ua) | C11: онлайн | D11: через маркетплейс | E11: bigl.ua | F11: 395 грн/кг | G11: 1 кг | H11: Найдешевший в Україні, але це залишки старого стоку: у 2025 світова ціна таурину зросла з $2 до $10/кг
A12: Таурин (для виробництва) | B12: ТОВ «Макрохім» | C12: Київ | D12: +380 (44) 495 27 00, info@macrochem.ua | E12: macrochem.ua/harchova-promyslovist/harchovi-dobavky/tauryn | F12: за запитом | G12: від 1 кг | H12: Харчова кваліфікація, Китай. Обов'язково фіксуйте ціну контрактом на 3–6 місяців — ринок гарячий
A13: D-глюкуронолактон | B13: ТОВ «Хімлаборреактив» | C13: Київ | D13: +380 (44) 365 42 42 | E13: shop.hlr.ua | F13: за запитом | G13: 25 г, 500 г | H13: УВАГА: кваліфікація «для синтезу» — це реактив, для напою формально не підходить. Харчову якість треба везти з Китаю (від 25 кг). Не сплутати з глюконо-дельта-лактоном E575!
A14: Інозитол | B14: ТОВ «Юнатіс» | C14: Буча, Київська обл. | D14: +380 (67) 503 88 17, +380 (67) 440 45 94, zakaz@ingredient.top | E14: lactose.com.ua | F14: ціна на сторінці товару | G14: опт і роздріб | H14: Прямо заявляють постачання для виробників, лабораторій, ФОП і ТОВ
A15: Вітамін B3 — нікотинамід | B15: ТОВ «СРП» | C15: Запоріжжя | D15: +38 (097) 987 13 76, info@tov-srp.com | E15: srp.ua | F15: 2 000 грн/кг (1 кг); 1 900 грн/кг від 10 кг | G15: 1 кг | H15: CAS 98-92-0, кристал. Працюють з ФОП і ТОВ, відправка того ж дня
A16: Вітамін B5, B2 (рибофлавін) | B16: FERM | C16: онлайн | D16: 0 800 20 11 88 | E16: ferm.ua | F16: ціна на сторінці товару | G16: 1 кг | H16: Є готові позиції «Вітамін B5 (кальцію пантотенат), 1 кг» і «Вітамін B2 (рибофлавін), 1 кг»
A17: Вітаміни B6, B12 | B17: ТОВ «Макрохім» / «Система Оптимум» | C17: Київ / Західна Україна | D17: 044 495 27 00; 050 138 50 61, 067 675 25 81 | E17: macrochem.ua, systopt.com.ua | F17: за запитом | G17: опт і роздріб | H17: B12 у формі 1 % trituration в Україні публічно не продають — або мікродоза чистого, або власне розведення
... A20: Екстракт зеленого чаю (опційно) | B20: ТОВ «БІОЛАЙН» | C20: Лубни, Полтавська обл. | D20: biolin.com.ua | E20: prom.ua | F20: 1 500 грн/кг; 1 400 грн/кг від 10 кг | G20: 1 кг | H20: Сухий екстракт, готовий до відправки
A21: СИРОВИНА — основа, кислоти, консерванти
A22: Цукор білий | B22: ринок (оптові трейдери) | C22: по всій Україні | D22: — | E22: — | F22: ≈31 грн/кг (ринковий орієнтир) | G22: від 1 т | H22: Заводи (Астарта, Радехівський цукор) працюють лише з великими обсягами — беріть у трейдерів
A23: Глюкозно-фруктозний сироп (ГФС-55) | B23: ТОВ «СРП» | C23: Запоріжжя | D23: +380 97 987 13 76 | E23: tov-srp.com | F23: 99 грн/кг від 50 кг; 39 грн/кг від 800 кг; 33 грн/кг від 2400 кг | G23: 50 кг (бочка) | H23: Найреалістичніша позиція для малих обсягів: публікує прайс і продає від однієї бочки
A24: ГФС-55 (виробник) | B24: Interstarch Ukraine | C24: Київ / Дніпровське | D24: website@interstarch.com.ua | E24: interstarch.com.ua | F24: за запитом | G24: промислова | H24: Єдиний підтверджений виробник ГФС в Україні (майданчик — Дніпровський крохмалепатоковий комбінат)
A25: Лимонна кислота E330 | B25: ТОВ «СРП» | C25: Запоріжжя | D25: +380 97 987 13 76 | E25: tov-srp.com | F25: 115 грн/кг (мішок 25 кг); 88 грн/кг від 40 мішків | G25: 1 кг | H25: Публікує повний прайс — найзручніший постачальник кислот
A26: Натрію цитрат E331 | B26: ТОВ «ХімСвіт» | C26: Харків | D26: 050/068 442 28 80, shop@himsvit.com.ua | E26: himsvit.com.ua | F26: 99 грн/кг (2 475 грн за 25 кг) | G26: 25 кг | H26: Також є «ФармХіміка» на Prom.ua — 3 200 грн/25 кг
A27: Яблучна кислота E296 | B27: ТОВ «ХімСвіт» | C27: Харків | D27: 050/068 442 28 80, shop@himsvit.com.ua | E27: himsvit.com.ua | F27: 145 грн/кг (3 625 грн за 25 кг) | G27: 25 кг | H27: Для класичного енергетика не обов'язкова — достатньо лимонної
A28: Аскорбінова кислота E300 | B28: Агробіз | C28: онлайн | D28: через сайт | E28: agrobiz.net | F28: ≈146 грн/кг (3 650 грн за 25 кг) | G28: 25 кг | H28: Ціну варто перепідтвердити запитом
A29: Ортофосфорна кислота E338 (85 %) | B29: Prom.ua (постачальники) | C29: Київ | D29: через маркетплейс | E29: prom.ua | F29: ≈1 650 грн за каністру 10 л (17 кг) ≈ 97 грн/кг | G29: 10 л | H29: Потрібна лише для смаку «кола», для класичного енергетика не обов'язкова
A30: Натрію бензоат E211 | B30: Klebrig | C30: Рівне | D30: +380 67 117 89 00, klebrig.sales@gmail.com | E30: klebrig.com.ua | F30: 182 грн/0,5 кг; 299 грн/1 кг | G30: 0,5 кг | H30: Головна перевага — працює з фасовками від 500 г, ідеально для пробних партій
A31: Калію сорбат E202 | B31: Klebrig | C31: Рівне | D31: +380 67 117 89 00, klebrig.sales@gmail.com | E31: klebrig.com.ua | F31: 229 грн/0,5 кг; 765 грн/2 кг; 1 398 грн/4 кг | G31: 0,5 кг | H31: Разом із бензоатом дає надійний захист напою при pH нижче 4
A32: СИРОВИНА — смак, колір, газ
A33: Ароматизатор «енергетик» | B33: ТОВ «Трумікс-Україна» (Truemix) | C33: с. Муроване, Львівська обл. | D33: +380 99 046 85 44, info@truemix.com.ua | E33: truemix.com.ua | F33: за запитом | G33: за запитом | H33: Український виробник ароматизаторів, ISO 22000, має напрям «напої»
A34: Ароматизатор (кола, фрукти) | B34: Б2Ф Україна (представник Robertet, Франція) | C34: Київ | D34: +380 50 414 66 75, +380 44 392 91 98, info@b2f-ukraine.org | E34: b2f.org.ua | F34: за запитом | G34: за запитом | H34: Є готові аромати «Кола», «Грейпфрут», «Полуниця», «Кавун», «Вишня», екстракт лимона
A35: Ароматизатор (проби) | B35: Flavors.ua | C35: онлайн | D35: через сайт | E35: flavors.ua | F35: флакони 100–120 мл | G35: 1 флакон | H35: Для домашніх пробних варок 20–50 л — саме те, що потрібно на першому тижні
A36: Барвник карамель E150d | B36: Bigl.ua (імпорт, Франція) | C36: онлайн | D36: через маркетплейс | E36: bigl.ua | F36: 98 грн за фасовку «на 100 л» | G36: 1 фасовка | H36: Зручно для проб, але для виробництва купуйте колер навалом — фасовки в 5–10 разів дорожчі за кг
A37: Рибофлавін E101 (жовтий) | B37: Харків-Торг | C37: Харків | D37: через сайт | E37: harkiv-torg.com.ua | F37: за запитом | G37: 1 кг | H37: Альтернатива колеру — дає «кислотно-жовтий» колір
A38: Діоксид вуглецю CO2 (балони) | B38: ТОВ «Пожарка» | C38: Київ | D38: 0 800 600 101 | E38: firecontrol.com.ua | F38: 748,80 грн за балон 40 л / 22 кг = 34 грн/кг | G38: 1 балон | H38: На 5 000 л/міс потрібно ≈1 балон на місяць — найдешевша стаття витрат
A39: Діоксид вуглецю CO2 (рідкий) | B39: АТ «Львівський хімічний завод» | C39: Львів | D39: +380 32 235 12 00 | E39: lhz.ua | F39: за запитом | G39: кріоцинстерна | H39: Харчовий CO2 виробництва Puławy (Польща), відповідає ISBT/EIGA, є висновок СЕС
A40: Вода: установка RO | B40: Ecosoft (ТОВ НВО «Екософт») | C40: Київ | D40: 044 490 61 69, office@ecosoft.ua | E40: ecosoft.ua | F40: MO12000 500 л/год — 149 625 грн | G40: 1 комплект | H40: Для 5 000 л/міс достатньо системи 150–250 л/год (≈40–60 тис. грн) + вугільна колона + УФ
A41: ТАРА ТА ПАКУВАННЯ
A42: Алюмінієва банка 0,33 л | B42: ТОВ «Кен-Пак (Україна)» / CANPACK | C42: м. Вишгород, Київська обл. | D42: (044) 496 97 80, office@canpack.com.ua | E42: canpack.com | F42: за запитом | G42: промислова (десятки тисяч шт + оснастка) | H42: Найбільший виробник банки в Україні, але для 5 000 л/міс практично недоступний
A43: Алюмінієва банка 0,33 л (малі партії) | B43: Velena | C43: Київ | D43: через сайт | E43: velena.com.ua | F43: за запитом, мінімальна сума замовлення 3 000 грн | G43: мін. кошик 3 000 грн | H43: Банки 330 мл Slim / Speed Open разом із кришками. Найреалістичніший варіант для малого обсягу
...

Sheet 4. Обладнання
A1: КОНТРАКТНЕ ВИРОБНИЦТВО, ОБЛАДНАННЯ ТА ПРИМІЩЕННЯ
A2: Курс НБУ: 1 USD = 44,86 грн, 1 EUR = 50,93 грн (вересень 2026). Ціни знайдені в реальних джерелах; те, що позначено «за запитом», у публічному доступі відсутнє — не вигадано.
A4: БЛОК 1. КОНТРАКТНЕ ВИРОБНИЦТВО (ко-пакінг) — рекомендований старт
A5: Компанія | B5: Місто | C5: Контакти | D5: Що розливає | E5: Мінімальна партія | F5: Ціна | G5: Примітка
A6: ТОВ «Балта» | B6: Запоріжжя | C6: balta.com.ua, contract@balta.com.ua, +38 063 744 92 80, +38 063 744 95 14 | D6: ПЕТ 0,5–6,0 л; алюмінієва банка 0,33 і 0,5 л; кега; bag-in-box. Прямо заявляє енергетики | E6: від 10 000 шт (≈3 300 л у банці 0,33) | F6: за запитом | G6: НАЙКРАЩИЙ ВАРІАНТ: повний цикл «під ключ» — рецептура, зразки, ТД і сертифікація, лабтести, дизайн і друк етикетки, закупівля банок, митниця, склад
A7: «Біолайт» | B7: Дніпро | C7: biolight.com.ua, office@biolight.com.ua, +38 096 498 91 28 | D7: Вода, соки, напої без газу та газовані | E7: «партії будь-якого розміру» | F7: індивідуальний розрахунок | G7: Є власна лабораторія. Обов'язково уточнити, чи є сатуратор для газованих напоїв
A8: Оболонь, Carlsberg, IDS, Coca-Cola HBC, Вітмарк, Росинка, Асканія | B8: по всій Україні | C8: — | D8: Великі обсяги | E8: індустріальна (десятки тисяч л) | F8: за запитом | G8: Публічних прайсів немає. Для 5 000 л/міс практично недосяжні
A10: ГОЛОВНА ПРОБЛЕМА: 5 000 л/міс — це НИЖЧЕ типового мінімуму ко-пакінгу. Автоматична банкова лінія (2 000–20 000 банок/год) виробить ваш місячний обсяг за 45 хвилин. Реальні мінімуми галузі — 20 000–100 000 банок (6 600–33 000 л). Рішення: замовляти партію раз на 1,5–4 місяці й тримати склад (термін придатності 12 міс. це дозволяє) або йти до «Балти» з порогом від 10 000 шт.
A12: БЛОК 2. ОБЛАДНАННЯ — РЕАЛЬНІ ЗНАЙДЕНІ ЦІНИ
A13: Позиція | B13: Виробник / продавець | C13: Ціна | D13: У грн | E13: Призначення | F13: Коментар
A14: Лінія розливу + закатки в банку CANSTART-250 (до 250 банок/год) | B14: Czech Brewery System (ЄС) | C14: €862 | D14: 43901.66 | E14: Розлив у банку | F14: Ручна/напівавтоматична мікролінія — саме те для 5 000 л/міс
A15: Закаточна машина UCS-300 CAN ULTRA SEAMER | B15: ЄС | C15: €820–990 | D15: 41762.6 | E15: Закатка банки | F15: Альтернатива до CANSTART
A16: Мобільна CIP-станція | B16: «Термо-Паб», Київ, +38 067 409 91 61 | C16: $1 095 | D16: 49121.7 | E16: Санітарія контуру | F16: Єдина публічна ціна в українського виробника
A17: Етикетувальник NPL-50 | B17: ABC Tech, abctech.com.ua | C17: 34 493 ₴ | D17: — | E17: Етикетка на ПЕТ | F17: До 40 шт/хв; ПЕТ клеїть лише наповненим
A18: Танк 1 000 л AISI 304 (без мішалки й сорочки) | B18: Bigl.ua | C18: 36 800 ₴ | D18: — | E18: Купаж | F18: Для повного циклу треба сорочку й мішалку — дорожче
A19: Лінія газованих напоїв 1 000 л/год (сатуратор + CIP + розлив) | B19: Suzhou Ellison (Китай), Made-in-China | C19: $10 000 | D19: 448600 | E19: Повний цикл ПЕТ | F19: Найдешевший повний китайський комплект
A20: Банкова лінія розливу й закатки 2 000–20 000 банок/год | B20: Zhangjiagang Proman (Китай) | C20: $25 000 | D20: 1121500 | E20: Повний цикл банки | F20: Продуктивність у 40+ разів більша за вашу потребу
A21: Установка водопідготовки RO 500 л/год | B21: Ecosoft MO12000 (Україна) | C21: 149 625 ₴ | D21: — | E21: Вода | F21: Для 5 000 л/міс достатньо 150–250 л/год (≈40–60 тис. грн)
A22: Приміщення: харчовий цех «під ключ» 200 м², Київ | B22: prozorro.sale (оренда) | C22: 139 000 ₴/міс | D22: — | E22: Виробництво | F22: 695 грн/м²/міс. Це 27,8 грн на літр — юніт-економіка не сходиться
A23: Приміщення: виробниче 90 м², Київ, вул. Ушинського | B23: bn.ua (оренда) | C23: 16 200 ₴/міс | D23: — | E23: Виробництво | F23: 180 грн/м²/міс. Київська обл. — 90–270 грн/м²/міс
A25: Бюджет міні-цеху: ручна мікролінія ≈$15 000–40 000 (банкова лінія €862–996 + танк + CIP $1 095 + етикетувальник + сатуратор і RO) плюс монтаж 5–10 %, приміщення й дозволи. Китайська автоматика — $70 000–100 000+. Але ручна лінія зробить ваш місячний обсяг за ~8 змін, тобто обладнання простоюватиме 90 % часу.
A27: БЛОК 3. ТРИ СЦЕНАРІЇ ЗАПУСКУ
A28: Сценарій | B28: Що потрібно | C28: Вкладення | D28: Плюси | E28: Мінуси
A29: A. Контрактний розлив (рекомендовано на старт) | B29: Рецептура + закупівля сировини + замовлення розливу (напр. «Балта» — від 10 000 шт) | C29: 150 000–500 000 ₴ | D29: Нуль витрат на обладнання, старт за 2–3 міс., можна тестувати смаки, партнер бере на себе ТД, сертифікацію й митницю | E29: Мінімальна партія 10 000–30 000 шт; менший контроль; вища ціна за літр; частину прибутку віддаєте партнеру
A30: B. Власний міні-цех | B30: Обладнання $15 000–40 000, приміщення 100–250 м², персонал, HACCP | C30: 1 500 000–4 500 000 ₴ | D30: Повний контроль, нижча собівартість, можна рости | E30: Оренда харчового цеху в Києві 695 ₴/м²/міс = до 27 ₴ на літр; обладнання простоює; довгий запуск 6–12 міс.
A31: C. Private label у готового виробника | B31: Готова рецептура виробника, ваш бренд | C31: 80 000–300 000 ₴ | D31: Найшвидший старт, мінімум мороки | E31: Не контролюєте склад і смак; тонка маржа; залежність від одного партнера
A33: ВИСНОВОК ДОСЛІДЖЕННЯ: стартувати треба з ПЕТ 0,5 л, а не з банки 0,33 л. Банка вимагає мінімальної партії 20 000+ шт і брендованої тари від 100 000 шт — це недосяжно на 5 000 л/міс. Тара для ПЕТ (пляшка 4,68 + кришка ≈0,60 + етикетка 0,17) ≈ 5,45 грн на пляшку 0,5 л проти ≈9,10 грн на банку 0,33 л. Банку додавайте після 20 000 л/міс.

Sheet 5. P&L 5000 л
A1: МІСЯЧНА ЕКОНОМІКА НА 5 000 Л (≈15 151 БАНКА 0,33 Л)
A2: Жовте — ввід. Змініть обсяг і ціну, щоб побачити свою картину.
A4: Показник | B4: Значення | C4: Од. | D4: Формула / пояснення
A5: Обсяг виробництва | B5: 5000 | C5: л | D5: Ваш план на місяць
A6: Кількість банок 0,33 л | B6: =B5/0.33 -> 15151.515 | C6: шт | D6: Обсяг / 0,33 л
A7: Відпускна ціна 1 банки без ПДВ | B7: 22 | C7: грн | D7: Ціна для дистриб'ютора або мережі. Полична ціна тоді ≈ 32–35 грн
A8: Виручка без ПДВ | B8: =B6*B7 -> 333333.33 | C8: грн | D8: Банки × ціна
A9: Змінні витрати (собівартість) | B9: =B6*'2. Собівартість'!E18 -> 276955.14 | C9: грн | D9: Банки × собівартість банки
A10: Валова маржа | B10: =B8-B9 -> 56378.198 | C10: грн | D10: Виручка − змінні витрати
A11: Валова маржа, % | B11: =IF(B8=0,0,B10/B8) -> 0.16913459 | C11: % | D11: Маржинальність
A12: Маржа на 1 банку | B12: =IF(B6=0,0,B10/B6) -> 3.7209611 | C12: грн | D12: Скільки лишається з банки
A13: — Постійні витрати —
A14: Оренда приміщення (0 — якщо контрактний розлив) | B14: 0 | C14: грн | D14: Власний цех 150 м² × 250 грн = 37 500 грн
A15: Адміністративна зарплата (власник, менеджер, бухгалтер) | B15: 25000 | C15: грн | D15: На старті власник працює сам — це головна економія
A16: Маркетинг і просування | B16: 20000 | C16: грн | D16: SMM, дегустації, промо в точках
A17: Логістика, склад, інше | B17: 8000 | C17: грн | D17: Оренда складу, паливо, зв'язок
A18: Разом постійні витрати | B18: =SUM(B14:B17) -> 53000 | C18: грн
A19: ОПЕРАЦІЙНИЙ ПРИБУТОК до податків | B19: =B10-B18 -> 3378.1978 | C19: грн | D19: Валова маржа − постійні
A20: Податок (ТОВ, податок на прибуток 18 % або ФОП 3 група 5 %) | B20: =MAX(0,B19)*0.05 -> 168.90989 | C20: грн | D20: Тут — оптимістичний варіант ФОП 3 групи
A21: ЧИСТИЙ ПРИБУТОК | B21: =B19-B20 -> 3209.2879 | C21: грн
A22: Точка беззбитковості, банок/міс | B22: =IF(B12<=0,"недосяжно: маржа на банку ≤ 0",B18/B12) -> 14243.632 | C22: шт | D22: Постійні витрати / маржа з банки
A23: Точка беззбитковості, літрів/міс | B23: =IF(B12<=0,"—",B22*0.33) -> 4700.3986 | C23: л
A26: Головний висновок моделі: на 5 000 л/міс проєкт працює «в нуль» — постійні витрати з'їдають майже всю маржу. Економіка з'являється з 30 000–50 000 банок на місяць. Тому на старт краще брати контрактний розлив і мінімум постійних витрат, а масштаб нарощувати продажами, а не обладнанням.
A28: ЧУТЛИВІСТЬ: ЩО БУДЕ З ПРИБУТКОМ ПРИ РІЗНИХ ОБСЯГАХ
A29: Рахується від тих самих ввідних даних вище (ціна, собівартість банки, постійні витрати).
A30: Обсяг, л/міс | B30: Банок 0,33 л | C30: Виручка без ПДВ, грн | D30: Змінні витрати, грн | E30: Маржинальний прибуток, грн | F30: Операційний прибуток, грн
A31: 2500 | B31: =A31/0.33 -> 7575.7576 | C31: =B31*$B$7 -> 166666.67 | D31: =B31*'2. Собівартість'!$E$18 -> 138477.57 | E31: =C31-D31 -> 28189.099 | F31: =E31-$B$18 -> -24810.901
A32: 5000 | B32: =A32/0.33 -> 15151.515 | C32: =B32*$B$7 -> 333333.33 | D32: =B32*'2. Собівартість'!$E$18 -> 276955.14 | E32: =C32-D32 -> 56378.198 | F32: =E32-$B$18 -> 3378.1978
A33: 10000 | B33: =A33/0.33 -> 30303.03 | C33: =B33*$B$7 -> 666666.67 | D33: =B33*'2. Собівартість'!$E$18 -> 553910.27 | E33: =C33-D33 -> 112756.4 | F33: =E33-$B$18 -> 59756.396
A34: 20000 | B34: =A34/0.33 -> 60606.061 | C34: =B34*$B$7 -> 1333333.3 | D34: =B34*'2. Собівартість'!$E$18 -> 1107820.5 | E34: =C34-D34 -> 225512.79 | F34: =E34-$B$18 -> 172512.79
A35: 30000 | B35: =A35/0.33 -> 90909.091 | C35: =B35*$B$7 -> 2000000 | D35: =B35*'2. Собівартість'!$E$18 -> 1661730.8 | E35: =C35-D35 -> 338269.19 | F35: =E35-$B$18 -> 285269.19
A36: 50000 | B36: =A36/0.33 -> 151515.15 | C36: =B36*$B$7 -> 3333333.3 | D36: =B36*'2. Собівартість'!$E$18 -> 2769551.4 | E36: =C36-D36 -> 563781.98 | F36: =E36-$B$18 -> 510781.98
A37: 100000 | B37: =A37/0.33 -> 303030.3 | C37: =B37*$B$7 -> 6666666.7 | D37: =B37*'2. Собівартість'!$E$18 -> 5539102.7 | E37: =C37-D37 -> 1127564 | F37: =E37-$B$18 -> 1074564
A39: Собівартість банки в цій таблиці взята незмінною. Насправді вона падає з обсягом: банка з друком, сировина й розлив дешевшають при великих партіях на 15–30 %. Тому реальна картина на 50 000 л/міс буде кращою, ніж показує розрахунок.

Sheet 6. Чекліст запуску
A1: ПОКРОКОВИЙ ПЛАН ЗАПУСКУ
A3: № | B3: Крок | C3: Що конкретно зробити | D3: Орієнтовний строк | E3: Статус
A4: 1 | B4: Рішення про продукт | C4: Визначити формат (банка 0,33 л), смак, назву, цінову нішу, канал продажу | D4: 1–2 тижні
A5: 2 | B5: Рецептура | C5: Затвердити склад і дози, зробити 2–3 пробні купажі (можна вручну, 20–50 л), дегустація | D5: 2–4 тижні
A6: 3 | B6: ТУ У або вибір ДСТУ | C6: Розробити й затвердити технічні умови України на напій, якщо не працюєте за ДСТУ | D6: 3–6 тижнів
A7: 4 | B7: Етикетка | C7: Розробити макет: склад, харчова цінність, вміст кофеїну, попередження, виробник, дата, умови зберігання | D7: 2–4 тижні
A8: 5 | B8: Перевірка маркування | C8: Перевірити макет на відповідність закону про інформацію для споживачів | D8: 1 тиждень
A9: 6 | B9: Пошук виробничого майданчика | C9: Запити на контрактний розлив: ціна за літр, мінімальна партія, умови зберігання сировини | D9: 2–6 тижнів
A10: 7 | B10: Постачальники сировини | C10: Запросити CoA і специфікації, ціни, мін. партії; замовити пробні партії | D10: 2–4 тижні
A11: 8 | B11: Тара | C11: Замовити банку й кришку, узгодити друк або слив-етикетку, мін. партію | D11: 3–8 тижнів
A12: 9 | B12: Реєстрація потужностей | C12: Подати повідомлення/реєстрацію потужностей до Держпродспоживслужби | D12: 1–3 тижні
A13: 10 | B13: HACCP | C13: Розробити й впровадити систему HACCP, вести журнали | D13: 1–2 місяці
A14: 11 | B14: Лабораторні випробування | C14: Здати партію на мікробіологію, вміст кофеїну, органолептику — отримати протокол | D14: 2–3 тижні
A15: 12 | B15: Перша партія | C15: Зварити й розлити пробну партію, закласти зразки на зберігання | D15: 2 тижні
... A17: 14 | B17: Облік і податки | C17: Обрати систему оподаткування, налагодити облік, перевірити обмеження для ФОП | D17: 1–2 тижні

Sheet 7. Квас з кофеїном 20 л
A1: БЕЗАЛКОГОЛЬНИЙ КВАС З КОФЕЇНОМ І ТАУРИНОМ — 20 Л
A2: Схема: ферментуємо цикорійну закваску (вона дає справжній квасний смак), ПАСТЕРИЗУЄМО її — дріжджі гинуть, бродіння зупиняється — і додаємо закваску як смаковий концентрат у безалкогольну основу разом із кофеїном і таурином. Фінальний напій виходить нижче 0,5 % об., тобто безалкогольним.
A4: КРОК 0. КАЛЬКУЛЯТОР МІЦНОСТІ — спочатку порахуйте, потім варіть
A5: Показник | B5: Значення | C5: Од. | D5: Як рахується
A6: Цільовий вміст спирту у фінальному напої | B6: 0.4 | C6: % об. | D6: ВВІД. Тримайте 0,35–0,40, щоб мати запас до порогу 0,5 %
A7: Міцність закваски після бродіння | B7: 2.1 | C7: % об. | D7: ВВІД. Заміряйте ареометром: (початкова густина − кінцева) × 131
A8: Максимальна частка закваски у фіналі | B8: =IF(B7=0,0,B6/B7) -> 0.19047619 | C8: % | D8: Рахунок: цільовий спирт поділити на міцність закваски. Більше — не можна
A9: Робоча частка закваски у фіналі | B9: 0.15 | C9: % | D9: ВВІД. Беріть із запасом, не «впритул»
A10: Спирт у фінальному напої | B10: =B7*B9 -> 0.315 | C10: % об. | D10: Рахунок: міцність закваски помножити на робочу частку. Мусить бути менше 0,50
A11: Запас до порогу 0,5 % | B11: =0.5-B10 -> 0.185 | C11: % об. | D11: Скільки ви маєте права на похибку бродіння
A12: Цукор у закваску для цієї міцності | B12: =B7*15.44 -> 32.424 | C12: г/л | D12: Рахунок: міцність помножити на 15,44. Бо 1 % об. = 7,89 г/л спирту = 15,44 г/л цукру
A13: Цукор у закваску на 20 л | B13: =B12*20/1000 -> 0.64848 | C13: кг | D13: Йде у рецептуру нижче автоматично
A15: ЕТАП 1. Ферментована цикорійна закваска (вихід 20 л)
A16: Компонент | B16: Кількість | C16: К-сть | D16: Од. | E16: Ціна за од., грн | F16: Вартість, грн | G16: Примітка
A17: Вода | B17: 20 л | C17: 20 | D17: л | E17: 0.15 | F17: =C17*E17 -> 3 | G17: Прокип'ятити й охолодити до 25 °C
A18: Цикорій (смажений мелений або розчинний) | B18: 250 г | C18: 0.25 | D18: кг | E18: 300 | F18: =C18*E18 -> 75 | G18: Заварити окремо, настояти 20 хв, процідити. Дає колір, гірчинку й «кавову» ноту
A19: Цукор | C19: =B13 -> 0.64848 | D19: кг | E19: 31 | F19: =C19*E19 -> 20.10288 | G19: Кількість рахується автоматично з калькулятора міцності
A20: Дріжджі сухі хлібопекарські | B20: 15 г | C20: 0.015 | D20: кг | E20: 800 | F20: =C20*E20 -> 12 | G20: 0,75 г/л. Більше не треба — з'явиться дріжджовий присмак
A21: Лимонна кислота | B21: 20 г | C21: 0.02 | D21: кг | E21: 115 | F21: =C21*E21 -> 2.3 | G21: Захищає від сторонньої мікрофлори
A22: РАЗОМ ЗАКВАСКА (вихід 20 л) | F22: =SUM(F17:F21) -> 112.40288
A23: Бродіння 3–4 доби при 20–24 °C під гідрозатвором або нещільною кришкою — НЕ закупорювати. Готовність визначають не за календарем, а за ареометром: коли густина перестала падати, бродіння закінчилось. Потім обов'язково заміряти міцність і ПАСТЕРИЗУВАТИ: 5–10 хв при 75–80 °C. Пастеризація вбиває дріжджі — саме вона робить напій безалкогольним і стабільним.
A25: ЕТАП 2. Фінальний напій (вихід 20 л)
A26: Компонент | B26: Кількість | C26: К-сть | D26: Од. | E26: Ціна за од., грн | F26: Вартість, грн | G26: Примітка
A27: Пастеризована закваска | C27: =20*B9 -> 3 | D27: л | E27: =F22/20 -> 5.620144 | F27: =C27*E27 -> 16.860432 | G27: Кількість = 20 л × робоча частка з калькулятора. Ціна = собівартість 1 л закваски
A28: Вода підготовлена | C28: =20-C27 -> 17 | D28: л | E28: 0.15 | F28: =C28*E28 -> 2.55 | G28: Доливається стільки, щоб разом із закваскою вийшло 20 л
A29: Цукор | B29: 1,3 кг | C29: 1.3 | D29: кг | E29: 31 | F29: =C29*E29 -> 40.3 | G29: 65 г/л. Класичний енергетик має 105 г/л, але для квасного смаку краще 60–70 г/л
A30: Лимонна кислота | B30: 15 г | C30: 0.015 | D30: кг | E30: 115 | F30: =C30*E30 -> 1.725 | G30: Довести pH до 3,2–3,6. Частину кислоти вже дає закваска
A31: Кофеїн безводний | B31: 6,4 г | C31: 0.0064 | D31: кг | E31: 1090 | F31: =C31*E31 -> 6.976 | G31: 320 мг/л — стандарт категорії. Розчинити у 0,5 л води 60–80 °C
A32: Таурин | B32: 80 г | C32: 0.08 | D32: кг | E32: 900 | F32: =C32*E32 -> 72 | G32: 4 г/л. Розчинити у 1,5–2 л води (розчинність близько 90 г/л)
A33: Нікотинамід (B3) | B33: 1,6 г | C33: 0.0016 | D33: кг | E33: 2000 | F33: =C33*E33 -> 3.2 | G33: 80 мг/л
A34: Кальцію D-пантотенат (B5) | B34: 0,4 г | C34: 0.0004 | D34: кг | E34: 1200 | F34: =C34*E34 -> 0.48 | G34: 20 мг/л. Терези з точністю 0,01 г обов'язкові
A35: Піридоксину гідрохлорид (B6) | B35: 0,4 г | C35: 0.0004 | D35: кг | E35: 1300 | F35: =C35*E35 -> 0.52 | G35: 20 мг/л. Вносити останнім при t ≤ 30 °C
A36: Ціанокобаламін B12 (1 % премікс) | B36: 40 мг | C36: 4e-05 | D36: кг | E36: 500 | F36: =C36*E36 -> 0.02 | G36: 2 мкг/л. Терезами не зважити — тільки через маточний розчин
A37: Калію сорбат E202 | B37: 4 г | C37: 0.004 | D37: кг | E37: 350 | F37: =C37*E37 -> 1.4 | G37: 0,2 г/л. Працює лише при pH < 4
A38: Натрію бензоат E211 | B38: 3 г | C38: 0.003 | D38: кг | E38: 299 | F38: =C38*E38 -> 0.897 | G38: 0,15 г/л — гранична норма. Вносити ДО кислоти
A39: РАЗОМ ФІНАЛЬНИЙ НАПІЙ (20 л) | F39: =SUM(F27:F38) -> 146.92843
A41: ПІДСУМОК
A42: Показник | B42: Значення | C42: Од. | D42: Пояснення
A43: Сировина на закваску (вихід 20 л) | B43: =F22 -> 112.40288 | C43: грн | D43: Закваски у фінальний напій іде лише частина, решта — на наступні партії
A44: Сировина на 20 л фінального напою | B44: =F39 -> 146.92843 | C44: грн | D44: Уже разом із закваскою, цукром, кофеїном і таурином
...

Sheet 8. Закупівля і посилання
A1: ЩО КУПИТИ, ДЕ КУПИТИ І СКІЛЬКИ ЦЕ КОШТУЄ
A2: Курс НБУ: 1 USD = 44,86 грн. Ціни — реальні з сайтів станом на вересень 2026. Цукор, дріжджі, вода — звичайний супермаркет. Усе інше — онлайн або спеціалізований постачальник.
A4: БЛОК 1. ЩО КУПИТИ (важкодоступні позиції)
A5: Позиція | B5: Де купити | C5: Посилання | D5: Ціна | E5: Мін. партія | F5: Вистачить на | G5: Примітка
A6: Кофеїн безводний | B6: ТОВ «Хімсейл», Київ, +38 099 537 90 00 | C6: chemsale.com.ua/ua/product/kofein/ | D6: 1 090 грн/кг | E6: 1 кг | F6: 3 125 л | G6: Специфікація 99,8 %, у наявності. Продають і фізособам
A7: Кофеїн безводний (проба) | B7: PROFIPROT через Bigl.ua | C7: bigl.ua/ua/p779662147-kofein-bezvodnyj-profiprot | D7: 195 грн/100 г | E7: 100 г | F7: 312 л | G7: Для першої проби дешевше, ніж кілограм. Для виробництва беріть у Хімсейла
A8: Таурин | B8: PROFIPROT через Bigl.ua | C8: bigl.ua/ua/p2667638736-taurin-aminokislota-profiprot | D8: 395 грн/кг | E8: 1 кг | F8: 250 л | G8: Це залишки старого стоку. Нові партії — 900–1400 грн/кг, уточнюйте перед закупівлею
A9: Таурин (для виробництва) | B9: ТОВ «Макрохім», Київ, 044 495 27 00 | C9: macrochem.ua/harchova-promyslovist/harchovi-dobavky/tauryn/ | D9: за запитом | E9: від 1 кг | F9: 250 л | G9: Харчова кваліфікація, Китай. Тут же кофеїн, B3 і B6 — можна одним замовленням
A10: Нікотинамід (B3) | B10: ТОВ «СРП», Запоріжжя, +38 097 987 13 76 | C10: srp.ua/shop/sipucha-ta-insha-himiya/nikotynamid/ | D10: 2 000 грн/кг | E10: 1 кг | F10: 12 500 л | G10: Найдорожча позиція першої закупівлі. Працюють з ФОП і ТОВ
A11: Пантотенат кальцію (B5) | B11: FERM, 0 800 20 11 88 | C11: ferm.ua/vitamin-v5-kal-pan-kal-cii-d-pantotenat-1-kg/p-17379 | D11: див. на сторінці | E11: 1 кг | F11: 50 000 л | G11: Готова фасовка 1 кг, доставка Новою Поштою
A12: Піридоксину гідрохлорид (B6) | B12: ТОВ «Юнатіс», Буча, +38 067 503 88 17 | C12: lactose.com.ua/ua/p1670104978-vitamin-piridoksinu-gidrohlorid.html | D12: 3 256 грн/кг | E12: 1 кг | F12: 50 000 л | G12: У наявності, 99 %. У цієї ж компанії є цикорій і ПЕТ-тара — можна взяти все одним замовленням
A13: Ціанокобаламін B12 | B13: «Система Оптимум», 050 138 50 61 | C13: systopt.com.ua/item-vitamin-v12-kobalamin | D13: за запитом | E13: уточнювати | F13: — | G13: 1 % премікс в Україні публічно майже не продають. Для проби — аптечні ампули
A14: Калію сорбат E202 | B14: Klebrig, Рівне, +38 067 117 89 00 | C14: klebrig.com.ua/ua/g87503765-kaliya-sorbat-pischevaya | D14: 229 грн/0,5 кг | E14: 0,5 кг | F14: 2 500 л | G14: Продають від 500 г — ідеально для проб. Тут же бензоат
A15: Натрію бензоат E211 | B15: Klebrig, Рівне, +38 067 117 89 00 | C15: klebrig.com.ua | D15: 182 грн/0,5 кг | E15: 0,5 кг | F15: 3 300 л | G15: Вносити ДО кислоти, інакше випадає в осад
A16: Лимонна кислота E330 | B16: ТОВ «СРП», Запоріжжя | C16: tov-srp.com/product/lymonna-kyslota-odnovodna/ | D16: 215 грн/1 кг; 115 грн/кг за мішок | E16: 1 кг | F16: 570 л | G16: Публікує повний прайс — найзручніший постачальник кислот
... A26: Газування: карбокап або сифон | B26: Prom.ua / Bigl.ua | C26: bigl.ua (пошук: сифон-сатуратор SodaStream) | D26: карбокап ≈300–600 грн; сифон 3 000–6 000 грн | E26: 1 шт | F26: — | G26: Після пастеризації дріжджів немає — газ тільки примусово
A28: БЛОК 2. ПОВНА СОБІВАРТІСТЬ 20 Л НАПОЮ
A29: Стаття | B29: Кількість | C29: Ціна за од., грн | D29: Сума, грн | E29: На 1 л, грн | F29: На пляшку 0,5 л, грн | G29: Коментар
A30: Закваска: цикорій | B30: 0.0375 | C30: 300 | D30: =B30*C30 -> 11.25 | E30: =D30/20 -> 0.5625 | F30: =D30/20*0.5 -> 0.28125 | G30: 250 г на 20 л закваски, у напій іде 15 % закваски
A31: Закваска: цукор | B31: 0.0975 | C31: 31 | D31: =B31*C31 -> 3.0225 | E31: =D31/20 -> 0.151125 | F31: =D31/20*0.5 -> 0.0755625 | G31: 650 г на закваску
A32: Закваска: дріжджі сухі | B32: 0.00225 | C32: 800 | D32: =B32*C32 -> 1.8 | E32: =D32/20 -> 0.09 | F32: =D32/20*0.5 -> 0.045 | G32: 15 г на закваску. У супермаркеті дріжджі дешевші
A33: Закваска: лимонна кислота | B33: 0.003 | C33: 115 | D33: =B33*C33 -> 0.345 | E33: =D33/20 -> 0.01725 | F33: =D33/20*0.5 -> 0.008625 | G33: 20 г на закваску
A34: Закваска: вода | B34: 3 | C34: 0.15 | D34: =B34*C34 -> 0.45 | E34: =D34/20 -> 0.0225 | F34: =D34/20*0.5 -> 0.01125 | G34: 3 л закваски у фінальному напої
A35: Вода питна | B35: 17 | C35: 0.15 | D35: =B35*C35 -> 2.55 | E35: =D35/20 -> 0.1275 | F35: =D35/20*0.5 -> 0.06375 | G35: Підготовлена або кип'ячена
A36: Цукор | B36: 1.3 | C36: 31 | D36: =B36*C36 -> 40.3 | E36: =D36/20 -> 2.015 | F36: =D36/20*0.5 -> 1.0075 | G36: 65 г/л у фінальному напої
A37: Лимонна кислота | B37: 0.015 | C37: 115 | D37: =B37*C37 -> 1.725 | E37: =D37/20 -> 0.08625 | F37: =D37/20*0.5 -> 0.043125 | G37: Довести pH до 3,2–3,6
A38: Кофеїн безводний | B38: 0.0064 | C38: 1090 | D38: =B38*C38 -> 6.976 | E38: =D38/20 -> 0.3488 | F38: =D38/20*0.5 -> 0.1744 | G38: 320 мг/л
A39: Таурин | B39: 0.08 | C39: 900 | D39: =B39*C39 -> 72 | E39: =D39/20 -> 3.6 | F39: =D39/20*0.5 -> 1.8 | G39: 4 г/л. Якщо встигнете купити по 395 грн/кг — ця стаття впаде вдвічі
A40: Нікотинамід B3 | B40: 0.0016 | C40: 2000 | D40: =B40*C40 -> 3.2 | E40: =D40/20 -> 0.16 | F40: =D40/20*0.5 -> 0.08 | G40: 80 мг/л
A41: Пантотенат кальцію B5 | B41: 0.0004 | C41: 1200 | D41: =B41*C41 -> 0.48 | E41: =D41/20 -> 0.024 | F41: =D41/20*0.5 -> 0.012 | G41: 20 мг/л
... A45: Натрію бензоат E211 | B45: 0.003 | C45: 299 | D45: =B45*C45 -> 0.897 | E45: =D45/20 -> 0.04485 | F45: =D45/20*0.5 -> 0.022425 | G45: 0,15 г/л
A46: СИРОВИНА РАЗОМ | D46: =SUM(D30:D45) -> 147.7179 | E46: =D46/20 -> 7.385895 | F46: =D46/20*0.5 -> 3.6929475
A47: ПЕТ-пляшка 0,5 л | B47: 40 | C47: 4.68 | D47: =B47*C47 -> 187.2 | E47: =D47/20 -> 9.36 | F47: =D47/20*0.5 -> 4.68 | G47: 40 пляшок на 20 л
A48: Кришка 28 мм | B48: 40 | C48: 0.6 | D48: =B48*C48 -> 24 | E48: =D48/20 -> 1.2 | F48: =D48/20*0.5 -> 0.6 | G48: Обов'язково під газовані напої
A49: Етикетка | B49: 40 | C49: 0.17 | D49: =B49*C49 -> 6.8 | E49: =D49/20 -> 0.34 | F49: =D49/20*0.5 -> 0.17 | G49: Самоклеюча, «Арт Віжн»
A50: Гофрокороб | B50: 4 | C50: 12.78 | D50: =B50*C50 -> 51.12 | E50: =D50/20 -> 2.556 | F50: =D50/20*0.5 -> 1.278 | G50: По 12 пляшок у коробі
A51: CO2 для газування | B51: 0.1 | C51: 34 | D51: =B51*C51 -> 3.4 | E51: =D51/20 -> 0.17 | F51: =D51/20*0.5 -> 0.085 | G51: 100 г на 20 л (5 г/л)
A52: ТАРА Й ПАКУВАННЯ РАЗОМ | D52: =SUM(D47:D51) -> 272.52 | E52: =D52/20 -> 13.626 | F52: =D52/20*0.5 -> 6.813
A53: РАЗОМ 20 Л ГОТОВОГО НАПОЮ | D53: =D46+D52 -> 420.2379 | E53: =D53/20 -> 21.011895 | F53: =D53/20*0.5 -> 10.505947
A55: Порівняння: класичний енергетик у банці 0,33 л має повну собівартість 18,28 грн, тобто 55,4 грн/л. Цей напій — орієнтовно 20 грн/л. Але тара й пакування тут — половина всієї суми, як і в будь-якому напої.
...

Sheet 9. Скло чи ПЕТ банка
A1: ТАРА ДЛЯ КРАФТОВОГО НАПОЮ: ПЕТ БАНКА, СКЛО, ПЕТ-ПЛЯШКА
A2: Ціни тари — знайдені в реальних магазинах (дрібний опт, вересень 2026). У колонці «гурт» — оцінка для закупівлі від 5 000 шт напряму з заводу: її треба підтвердити комерційною пропозицією. Жовті клітинки можна міняти на свої ціни.
A4: БЛОК 1. СКІЛЬКИ КОШТУЄ КОЖНА ТАРА
A5: Позиція | B5: Дрібний опт, грн | C5: Гурт від 5 000 шт, грн | D5: Мін. партія | E5: Де купити | F5: Примітка
A6: ПЕТ-пляшка 0,5 л (горло 28 мм) | B6: 4.68 | C6: 3.9 | D6: 160 шт | E6: prom.ua/p1432974873-butylka-pet-gorlom.html | F6: Найдешевша тара. Виглядає масово — для преміуму не годиться
A7: ПЕТ банка 0,33 л (кришка speed open) | B7: 16.64 | C7: 12 | D7: уточнювати | E7: prom.ua/ua/p2921557994-pet-tara-banka.html | F7: Формат «як алюмінієва банка», але пластиковий. Нішевий, тому дорогий
A8: ПЕТ банка 0,5 л (кришка 63 мм) | B8: 19.44 | C8: 14 | D8: 100 шт | E8: fabrika-upakovki.com/ua/p2122179911-banka-pet-500.html | F8: Квадратна банка з широкою кришкою. Теж нішевий формат
A9: Скляна пляшка 0,33 л (Long-neck, коричнева) | B9: 12.25 | C9: 11 | D9: уп. 360 шт | E9: «Інтерскло», Львів — sklotara.com | F9: НАЙДЕШЕВША підтверджена ціна. Без ПДВ, 100 % передоплата
A10: Скляна пляшка 0,5 л (Vichy Light, коричнева) | B10: 11.55 | C10: 10.5 | D10: уп. 300 шт | E10: «Інтерскло», Львів — sklotara.com | F10: ПАРАДОКС: 0,5 л дешевше за 0,33 л. Якщо об'єм не критичний — беріть 0,5
A11: Скляна пляшка 0,33 л (Ametist Glass, Київ) | B11: 15 | C11: 14 | D11: є на складі | E11: ametistglass.com | F11: Дорожче за Львів, але є в наявності сьогодні й ближче до Києва
A12: Скляна пляшка 0,5 л (прямокутна, вінчик) | B12: 26 | C12: 20 | D12: 20 шт | E12: kormushka.ua | F12: Прямокутна пляшка виглядає найдорожче. Для преміум-лінійки
A13: Пляшка 0,33 л УЖЕ З КРОНЕНПРОБКОЮ | B13: 13.7 | C13: 13 | D13: опт | E13: «Домашнє Діло», Flagma | F13: Зручно: пробку не купувати окремо. Контакти за реєстрацією на Flagma
A14: Кроненпробка Ø26 мм | B14: 0.7 | C14: 0.55 | D14: уп. 100 шт | E14: «Інтерскло», Львів | F14: Найдешевша підтверджена. У роздріб у Києві — 2 ₴/шт, тобто втричі дорожче
A15: Б/в мита скляна пляшка 0,5 л | B15: 6 | C15: 5 | D15: уточнювати | E15: приватні продавці, Flagma | F15: НАЙБІЛЬШИЙ ВАЖІЛЬ ЕКОНОМІЇ: на 5000 пляшок це 30 000–35 000 ₴. Але обсяги не гарантовані
A16: Етикетка самоклеюча (ПЕТ) | B16: 0.17 | C16: 0.12 | D16: 1 000 шт | E16: av.vn.ua/largeprint/druk-etyketok-kyiv/ | F16: Дешево, але виглядає масово
A17: Етикетка паперова (скло) | B17: 0.7 | C17: 0.45 | D17: 1 000 шт | E17: av.vn.ua або goodwillpack.com.ua | F17: Папір + кроненпробка = класичний крафтовий вигляд
A18: Гофрокороб (12 пляшок) | B18: 12.78 | C18: 11 | D18: 100 шт | E18: aspak.com.ua | F18: Скло важче — короб має бути міцнішим
A20: БЛОК 2. СОБІВАРТІСТЬ ОДИНИЦІ ЗА ФОРМАТАМИ
A21: Стаття | B21: ПЕТ-пляшка 0,5 л | C21: ПЕТ банка 0,33 л | D21: Скло 0,33 л | E21: Скло 0,5 л | F21: Коментар
A22: Тара | B22: 4.68 | C22: 16.64 | D22: 12.25 | E22: 11.55 | F22: Скло — «Інтерскло», Львів, без ПДВ. ПЕТ — дрібний опт
A23: Кришка / кроненпробка | B23: 0.6 | C23: 0 | D23: 0.7 | E23: 0.7 | F23: Кронен Ø26 — «Інтерскло» 0,70 грн. У ПЕТ банки кришка входить у ціну
A24: Етикетка | B24: 0.17 | C24: 0.6 | D24: 1.5 | E24: 1.8 | F24: На скло — паперова, більша й дорожча за самоклеючу
A25: Гофрокороб (на одиницю) | B25: 1.07 | C25: 0.9 | D25: 0.9 | E25: 1.07 | F25: 12 пляшок у коробі
A26: ТАРА РАЗОМ, грн | B26: =SUM(B22:B25) -> 6.52 | C26: =SUM(C22:C25) -> 18.14 | D26: =SUM(D22:D25) -> 15.35 | E26: =SUM(E22:E25) -> 15.12
A27: Об'єм одиниці, л | B27: 0.5 | C27: 0.33 | D27: 0.33 | E27: 0.5
A28: Тара на 1 літр, грн | B28: =B26/B27 -> 13.04 | C28: =C26/C27 -> 54.969697 | D28: =D26/D27 -> 46.515152 | E28: =E26/E27 -> 30.24
A29: Напій в одиниці, грн | B29: ='8. Закупівля і посилання'!E46*B27 -> 3.6929475 | C29: ='8. Закупівля і посилання'!E46*C27 -> 2.4373454 | D29: ='8. Закупівля і посилання'!E46*D27 -> 2.4373454 | E29: ='8. Закупівля і посилання'!E46*E27 -> 3.6929475 | F29: Береться собівартість сировини з листа 8
A30: ПОВНА СОБІВАРТІСТЬ ОДИНИЦІ, грн | B30: =B26+B29 -> 10.212948 | C30: =C26+C29 -> 20.577345 | D30: =D26+D29 -> 17.787345 | E30: =E26+E29 -> 18.812947
A31: Собівартість 1 літра в цій тарі, грн | B31: =B30/B27 -> 20.425895 | C31: =C30/C27 -> 62.355592 | D31: =D30/D27 -> 53.901047 | E31: =E30/E27 -> 37.625895
A32: Одиниць із 20 л | B32: =20/B27 -> 40 | C32: =20/C27 -> 60.606061 | D32: =20/D27 -> 60.606061 | E32: =20/E27 -> 40
A33: Тара на партію 20 л, грн | B33: =B32*B26 -> 260.8 | C33: =C32*C26 -> 1099.3939 | D33: =D32*D26 -> 930.30303 | E33: =E32*E26 -> 604.8
A35: БЛОК 3. ЦІНОВЕ ПОЗИЦІОНУВАННЯ І МАРЖА
A36: Формат | B36: Собівартість одиниці | C36: Ціна для магазину (ввід) | D36: Націнка, грн | E36: Націнка, % | F36: Полична ціна (магазин +35 %) | G36: Коментар
A37: ПЕТ-пляшка 0,5 л | B37: =B30 -> 10.212948 | C37: 22 | D37: =C37-B37 -> 11.787052 | E37: =IF(B37=0,0,D37/B37) -> 1.1541284 | F37: =C37*1.35 -> 29.7 | G37: Для цього формату преміум-ціну не поставиш — покупець порівняє з водою
A38: ПЕТ банка 0,33 л | B38: =C30 -> 20.577345 | C38: 45 | D38: =C38-B38 -> 24.422655 | E38: =IF(B38=0,0,D38/B38) -> 1.186871 | F38: =C38*1.35 -> 60.75 | G38: Виглядає як банка, але в руці відчувається пластик
A39: Скло 0,33 л | B39: =D30 -> 17.787345 | C39: 55 | D39: =C39-B39 -> 37.212655 | E39: =IF(B39=0,0,D39/B39) -> 2.0920859 | F39: =C39*1.35 -> 74.25 | G39: Класичний крафт: скло + кроненпробка + паперова етикетка
A40: Скло 0,5 л | B40: =E30 -> 18.812947 | C40: 75 | D40: =C40-B40 -> 56.187053 | E40: =IF(B40=0,0,D40/B40) -> 2.9866161 | F40: =C40*1.35 -> 101.25 | G40: Прямокутна пляшка 0,5 л — найдорожча полиця
A42: ГОЛОВНИЙ ВИСНОВОК: ПЕТ банка виявилась НАЙДОРОЖЧОЮ тарою — 16,64 грн за 0,33 л, дорожче за скляну пляшку (14,40) і вчетверо дорожче за ПЕТ-пляшку в перерахунку на літр. Це нішевий формат з кришкою speed open, його майже ніхто не використовує масово. Для крафтового позиціонування скло і дешевше, і виглядає правильніше.
A43: АЛЕ СКЛО МАЄ СВОЮ ЦІНУ: собівартість літра в склі в 3–4 рази вища, ніж у ПЕТ-пляшці. Зате й полична ціна інша: у склі ви ставите 55–75 грн за пляшку проти 22 грн у ПЕТ. Маржа з пляшки зростає приблизно втричі — саме тому крафт у склі має сенс.
A45: БЛОК 4. ЩО ВРАХУВАТИ САМЕ ДЛЯ СКЛА
...
